load GCC/8.3.0 (PATH, MANPATH, INFOPATH, LIBRARY_PATH, LD_LIBRARY_PATH, STD
COMP VARS) 
load FFMPEG/4.2.1 (PATH, LIBRARY_PATH, PKG_CONFIG_PATH, C_INCLUDE_PATH,
CPLUS_INCLUDE_PATH) 
load CUDA/10.2 (PATH, MANPATH, LD_LIBRARY_PATH, LIBRARY_PATH, C_INCLUDE_PATH,
CPLUS_INCLUDE_PATH, CUDA_HOME, CUDA_VERSION, CUDA_INC, CUDA_INSTALL_PATH) 
load CUDNN/7.6.4 (LD_LIBRARY_PATH, LIBRARY_PATH, C_INCLUDE_PATH,
CPLUS_INCLUDE_PATH, CUDNN_LIB_DIR, CUDNN_LIBRARY, CUDNN_INCLUDE_DIR) 
load NCCL/2.4.8 (LD_LIBRARY_PATH, LIBRARY_PATH, C_INCLUDE_PATH,
CPLUS_INCLUDE_PATH) 
load TENSORRT/6.0.1 (PATH, LD_LIBRARY_PATH, LIBRARY_PATH, C_INCLUDE_PATH,
CPLUS_INCLUDE_PATH) 
load OPENMPI/4.0.1 (PATH, MANPATH, LD_LIBRARY_PATH, LIBRARY_PATH,
PKG_CONFIG_PATH, C_INCLUDE_PATH, CPLUS_INCLUDE_PATH, MPI, MPI_V) 
load ATLAS/3.10.3 (LD_LIBRARY_PATH, LIBRARY_PATH, C_INCLUDE_PATH,
CPLUS_INCLUDE_PATH) 
load SCALAPACK/2.0.2 (LD_LIBRARY_PATH, LIBRARY_PATH, PKG_CONFIG_PATH) 
load FFTW/3.3.8 (PATH, MANPATH, LD_LIBRARY_PATH, LIBRARY_PATH, C_INCLUDE_PATH,
CPLUS_INCLUDE_PATH, PKG_CONFIG_PATH) 
load SZIP/2.1.1 (LD_LIBRARY_PATH, LIBRARY_PATH, C_INCLUDE_PATH,
CPLUS_INCLUDE_PATH) 
load OPENCV/4.1.1 (PATH, LD_LIBRARY_PATH, LIBRARY_PATH, C_INCLUDE_PATH,
CPLUS_INCLUDE_PATH, PYTHONPATH) 
load PYTHON/3.7.4_ML (PATH, MANPATH, LD_LIBRARY_PATH, LIBRARY_PATH,
PKG_CONFIG_PATH, C_INCLUDE_PATH, CPLUS_INCLUDE_PATH, PYTHONHOME, PYTHONPATH,
OMPI_MCA_mpi_warn_on_fork, PROTOCOL_BUFFERS_PYTHON_IMPLEMENTATION,
PROTOCOL_BUFFERS_PYTHON_IMPLEMENTATION_VERSION) 
2022-04-28 11:01:39.917904: I tensorflow/stream_executor/platform/default/dso_loader.cc:48] Successfully opened dynamic library libcudart.so.10.2
2022-04-28 11:01:57.446198: I tensorflow/stream_executor/platform/default/dso_loader.cc:48] Successfully opened dynamic library libcuda.so.1
2022-04-28 11:01:57.488622: I tensorflow/core/common_runtime/gpu/gpu_device.cc:1716] Found device 0 with properties: 
pciBusID: 0004:04:00.0 name: Tesla V100-SXM2-16GB computeCapability: 7.0
coreClock: 1.53GHz coreCount: 80 deviceMemorySize: 15.75GiB deviceMemoryBandwidth: 836.37GiB/s
2022-04-28 11:01:57.488668: I tensorflow/stream_executor/platform/default/dso_loader.cc:48] Successfully opened dynamic library libcudart.so.10.2
2022-04-28 11:01:57.541733: I tensorflow/stream_executor/platform/default/dso_loader.cc:48] Successfully opened dynamic library libcublas.so.10
2022-04-28 11:01:57.571218: I tensorflow/stream_executor/platform/default/dso_loader.cc:48] Successfully opened dynamic library libcufft.so.10
2022-04-28 11:01:57.603694: I tensorflow/stream_executor/platform/default/dso_loader.cc:48] Successfully opened dynamic library libcurand.so.10
2022-04-28 11:01:57.644442: I tensorflow/stream_executor/platform/default/dso_loader.cc:48] Successfully opened dynamic library libcusolver.so.10
2022-04-28 11:01:57.668192: I tensorflow/stream_executor/platform/default/dso_loader.cc:48] Successfully opened dynamic library libcusparse.so.10
2022-04-28 11:01:57.721279: I tensorflow/stream_executor/platform/default/dso_loader.cc:48] Successfully opened dynamic library libcudnn.so.7
2022-04-28 11:01:57.723797: I tensorflow/core/common_runtime/gpu/gpu_device.cc:1858] Adding visible gpu devices: 0
2022-04-28 11:01:57.774913: I tensorflow/core/platform/profile_utils/cpu_utils.cc:104] CPU Frequency: 3783000000 Hz
2022-04-28 11:01:57.777197: I tensorflow/compiler/xla/service/service.cc:168] XLA service 0x2dccb370 initialized for platform Host (this does not guarantee that XLA will be used). Devices:
2022-04-28 11:01:57.777266: I tensorflow/compiler/xla/service/service.cc:176]   StreamExecutor device (0): Host, Default Version
2022-04-28 11:01:57.888099: I tensorflow/compiler/xla/service/service.cc:168] XLA service 0x2dd37a30 initialized for platform CUDA (this does not guarantee that XLA will be used). Devices:
2022-04-28 11:01:57.888241: I tensorflow/compiler/xla/service/service.cc:176]   StreamExecutor device (0): Tesla V100-SXM2-16GB, Compute Capability 7.0
2022-04-28 11:01:57.891359: I tensorflow/core/common_runtime/gpu/gpu_device.cc:1716] Found device 0 with properties: 
pciBusID: 0004:04:00.0 name: Tesla V100-SXM2-16GB computeCapability: 7.0
coreClock: 1.53GHz coreCount: 80 deviceMemorySize: 15.75GiB deviceMemoryBandwidth: 836.37GiB/s
2022-04-28 11:01:57.891411: I tensorflow/stream_executor/platform/default/dso_loader.cc:48] Successfully opened dynamic library libcudart.so.10.2
2022-04-28 11:01:57.891478: I tensorflow/stream_executor/platform/default/dso_loader.cc:48] Successfully opened dynamic library libcublas.so.10
2022-04-28 11:01:57.891523: I tensorflow/stream_executor/platform/default/dso_loader.cc:48] Successfully opened dynamic library libcufft.so.10
2022-04-28 11:01:57.891567: I tensorflow/stream_executor/platform/default/dso_loader.cc:48] Successfully opened dynamic library libcurand.so.10
2022-04-28 11:01:57.891612: I tensorflow/stream_executor/platform/default/dso_loader.cc:48] Successfully opened dynamic library libcusolver.so.10
2022-04-28 11:01:57.891656: I tensorflow/stream_executor/platform/default/dso_loader.cc:48] Successfully opened dynamic library libcusparse.so.10
2022-04-28 11:01:57.891701: I tensorflow/stream_executor/platform/default/dso_loader.cc:48] Successfully opened dynamic library libcudnn.so.7
2022-04-28 11:01:57.894940: I tensorflow/core/common_runtime/gpu/gpu_device.cc:1858] Adding visible gpu devices: 0
2022-04-28 11:01:57.895700: I tensorflow/stream_executor/platform/default/dso_loader.cc:48] Successfully opened dynamic library libcudart.so.10.2
2022-04-28 11:01:58.677958: I tensorflow/core/common_runtime/gpu/gpu_device.cc:1257] Device interconnect StreamExecutor with strength 1 edge matrix:
2022-04-28 11:01:58.678037: I tensorflow/core/common_runtime/gpu/gpu_device.cc:1263]      0 
2022-04-28 11:01:58.678052: I tensorflow/core/common_runtime/gpu/gpu_device.cc:1276] 0:   N 
2022-04-28 11:01:58.683056: I tensorflow/core/common_runtime/gpu/gpu_device.cc:1402] Created TensorFlow device (/job:localhost/replica:0/task:0/device:GPU:0 with 14728 MB memory) -> physical GPU (device: 0, name: Tesla V100-SXM2-16GB, pci bus id: 0004:04:00.0, compute capability: 7.0)
Traceback (most recent call last):
  File "/apps/PYTHON/3.7.4_ML/lib/python3.7/urllib/request.py", line 1317, in do_open
    encode_chunked=req.has_header('Transfer-encoding'))
  File "/apps/PYTHON/3.7.4_ML/lib/python3.7/http/client.py", line 1244, in request
    self._send_request(method, url, body, headers, encode_chunked)
  File "/apps/PYTHON/3.7.4_ML/lib/python3.7/http/client.py", line 1290, in _send_request
    self.endheaders(body, encode_chunked=encode_chunked)
  File "/apps/PYTHON/3.7.4_ML/lib/python3.7/http/client.py", line 1239, in endheaders
    self._send_output(message_body, encode_chunked=encode_chunked)
  File "/apps/PYTHON/3.7.4_ML/lib/python3.7/http/client.py", line 1026, in _send_output
    self.send(msg)
  File "/apps/PYTHON/3.7.4_ML/lib/python3.7/http/client.py", line 966, in send
    self.connect()
  File "/apps/PYTHON/3.7.4_ML/lib/python3.7/http/client.py", line 1406, in connect
    super().connect()
  File "/apps/PYTHON/3.7.4_ML/lib/python3.7/http/client.py", line 938, in connect
    (self.host,self.port), self.timeout, self.source_address)
  File "/apps/PYTHON/3.7.4_ML/lib/python3.7/socket.py", line 727, in create_connection
    raise err
  File "/apps/PYTHON/3.7.4_ML/lib/python3.7/socket.py", line 716, in create_connection
    sock.connect(sa)
OSError: [Errno 101] Network is unreachable

During handling of the above exception, another exception occurred:

Traceback (most recent call last):
  File "/apps/PYTHON/3.7.4_ML/lib/python3.7/site-packages/tensorflow/python/keras/utils/data_utils.py", line 278, in get_file
    urlretrieve(origin, fpath, dl_progress)
  File "/apps/PYTHON/3.7.4_ML/lib/python3.7/urllib/request.py", line 247, in urlretrieve
    with contextlib.closing(urlopen(url, data)) as fp:
  File "/apps/PYTHON/3.7.4_ML/lib/python3.7/urllib/request.py", line 222, in urlopen
    return opener.open(url, data, timeout)
  File "/apps/PYTHON/3.7.4_ML/lib/python3.7/urllib/request.py", line 525, in open
    response = self._open(req, data)
  File "/apps/PYTHON/3.7.4_ML/lib/python3.7/urllib/request.py", line 543, in _open
    '_open', req)
  File "/apps/PYTHON/3.7.4_ML/lib/python3.7/urllib/request.py", line 503, in _call_chain
    result = func(*args)
  File "/apps/PYTHON/3.7.4_ML/lib/python3.7/urllib/request.py", line 1360, in https_open
    context=self._context, check_hostname=self._check_hostname)
  File "/apps/PYTHON/3.7.4_ML/lib/python3.7/urllib/request.py", line 1319, in do_open
    raise URLError(err)
urllib.error.URLError: <urlopen error [Errno 101] Network is unreachable>

During handling of the above exception, another exception occurred:

Traceback (most recent call last):
  File "ex3.py", line 36, in <module>
    model= tf.keras.applications.DenseNet121(include_top=False, input_shape=(img_width,img_width,3), weights="imagenet")
  File "/apps/PYTHON/3.7.4_ML/lib/python3.7/site-packages/tensorflow/python/keras/applications/densenet.py", line 330, in DenseNet121
    input_shape, pooling, classes)
  File "/apps/PYTHON/3.7.4_ML/lib/python3.7/site-packages/tensorflow/python/keras/applications/densenet.py", line 300, in DenseNet
    file_hash='30ee3e1110167f948a6b9946edeeb738')
  File "/apps/PYTHON/3.7.4_ML/lib/python3.7/site-packages/tensorflow/python/keras/utils/data_utils.py", line 282, in get_file
    raise Exception(error_msg.format(origin, e.errno, e.reason))
Exception: URL fetch failure on https://storage.googleapis.com/tensorflow/keras-applications/densenet/densenet121_weights_tf_dim_ordering_tf_kernels_notop.h5: None -- [Errno 101] Network is unreachable
